Workbook

Sheet Sheet1
A1: MLFB Код | C1: 6MD66415EB250AA3----------------
A2: Версия ПО терминала | C2: V04.70.02
A3: Топология | C3: TEST / Аэропорт / ВТ1 / 6MD664 V4.7 АУВ В 220 Т-
A4: Версия SiemensPie | C4: C5B12D13
A5: Конфигурация устройства
A6: Адрес | B6: Параметр | C6: Значение/диапазон/шаг | D6: Задаваемый параметр | H6: Комментарий
I7: 1 | J7: 2 | K7: 3 | L7: 4 | M7: 1 | N7: 2 | O7: 3 | P7: 4
A8: 0103 | B8: Переключ Группы | C8: Выведено_x000D_ Введено | D8: Выведено | H8: Опция переключения группы уставок | I8: =TRIM(SUBSTITUTE(INDEX([1]ТУ!$A:$G,MATCH($A8,[1]ТУ!$A:$A,0),3+I$7),"*","")) -> Выведено | J8: =TRIM(SUBSTITUTE(INDEX([1]ТУ!$A:$G,MATCH($A8,[1]ТУ!$A:$A,0),3+J$7),"*","")) | K8: =TRIM(SUBSTITUTE(INDEX([1]ТУ!$A:$G,MATCH($A8,[1]ТУ!$A:$A,0),3+K$7),"*","")) | L8: =TRIM(SUBSTITUTE(INDEX([1]ТУ!$A:$G,MATCH($A8,[1]ТУ!$A:$A,0),3+L$7),"*","")) | M8: =IF($A8<>"",IFERROR(IF(SUBSTITUTE(D8,",",".")<>SUBSTITUTE(SUBSTITUTE(I8,",","."),"∞","oo"),1,""),"!"),"") | N8: =IF($A8<>"",IFERROR(IF(SUBSTITUTE(E8,",",".")<>SUBSTITUTE(SUBSTITUTE(J8,",","."),"∞","oo"),1,""),"!"),"") | O8: =IF($A8<>"",IFERROR(IF(SUBSTITUTE(F8,",",".")<>SUBSTITUTE(SUBSTITUTE(K8,",","."),"∞","oo"),1,""),"!"),"") | P8: =IF($A8<>"",IFERROR(IF(SUBSTITUTE(G8,",",".")<>SUBSTITUTE(SUBSTITUTE(L8,",","."),"∞","oo"),1,""),"!"),"")
A9: 0x2000016769F1 | B9: Изм U_1 | C9: Выведено_x000D_ Введено | D9: Введено | H9: Измерение U | I9: =TRIM(SUBSTITUTE(INDEX([1]ТУ!$A:$G,MATCH($A9,[1]ТУ!$A:$A,0),3+I$7),"*","")) -> Введено | J9: =TRIM(SUBSTITUTE(INDEX([1]ТУ!$A:$G,MATCH($A9,[1]ТУ!$A:$A,0),3+J$7),"*","")) | K9: =TRIM(SUBSTITUTE(INDEX([1]ТУ!$A:$G,MATCH($A9,[1]ТУ!$A:$A,0),3+K$7),"*","")) | L9: =TRIM(SUBSTITUTE(INDEX([1]ТУ!$A:$G,MATCH($A9,[1]ТУ!$A:$A,0),3+L$7),"*","")) | M9: =IF($A9<>"",IFERROR(IF(SUBSTITUTE(D9,",",".")<>SUBSTITUTE(SUBSTITUTE(I9,",","."),"∞","oo"),1,""),"!"),"") | N9: =IF($A9<>"",IFERROR(IF(SUBSTITUTE(E9,",",".")<>SUBSTITUTE(SUBSTITUTE(J9,",","."),"∞","oo"),1,""),"!"),"") | O9: =IF($A9<>"",IFERROR(IF(SUBSTITUTE(F9,",",".")<>SUBSTITUTE(SUBSTITUTE(K9,",","."),"∞","oo"),1,""),"!"),"") | P9: =IF($A9<>"",IFERROR(IF(SUBSTITUTE(G9,",",".")<>SUBSTITUTE(SUBSTITUTE(L9,",","."),"∞","oo"),1,""),"!"),"")
A10: 0x2000016769F2 | B10: Изм I_1 | C10: Выведено_x000D_ Введено | D10: Выведено | H10: Измерение I | I10: =TRIM(SUBSTITUTE(INDEX([1]ТУ!$A:$G,MATCH($A10,[1]ТУ!$A:$A,0),3+I$7),"*","")) -> Выведено | J10: =TRIM(SUBSTITUTE(INDEX([1]ТУ!$A:$G,MATCH($A10,[1]ТУ!$A:$A,0),3+J$7),"*","")) | K10: =TRIM(SUBSTITUTE(INDEX([1]ТУ!$A:$G,MATCH($A10,[1]ТУ!$A:$A,0),3+K$7),"*","")) | L10: =TRIM(SUBSTITUTE(INDEX([1]ТУ!$A:$G,MATCH($A10,[1]ТУ!$A:$A,0),3+L$7),"*","")) | M10: =IF($A10<>"",IFERROR(IF(SUBSTITUTE(D10,",",".")<>SUBSTITUTE(SUBSTITUTE(I10,",","."),"∞","oo"),1,""),"!"),"") | N10: =IF($A10<>"",IFERROR(IF(SUBSTITUTE(E10,",",".")<>SUBSTITUTE(SUBSTITUTE(J10,",","."),"∞","oo"),1,""),"!"),"") | O10: =IF($A10<>"",IFERROR(IF(SUBSTITUTE(F10,",",".")<>SUBSTITUTE(SUBSTITUTE(K10,",","."),"∞","oo"),1,""),"!"),"") | P10: =IF($A10<>"",IFERROR(IF(SUBSTITUTE(G10,",",".")<>SUBSTITUTE(SUBSTITUTE(L10,",","."),"∞","oo"),1,""),"!"),"")
A11: 0x2000016769F3 | B11: Изм 1ф_1 | C11: Выведено_x000D_ Введено | D11: Введено | H11: Однофазное измерение, группа измерений 1 | I11: =TRIM(SUBSTITUTE(INDEX([1]ТУ!$A:$G,MATCH($A11,[1]ТУ!$A:$A,0),3+I$7),"*","")) -> Введено | J11: =TRIM(SUBSTITUTE(INDEX([1]ТУ!$A:$G,MATCH($A11,[1]ТУ!$A:$A,0),3+J$7),"*","")) | K11: =TRIM(SUBSTITUTE(INDEX([1]ТУ!$A:$G,MATCH($A11,[1]ТУ!$A:$A,0),3+K$7),"*","")) | L11: =TRIM(SUBSTITUTE(INDEX([1]ТУ!$A:$G,MATCH($A11,[1]ТУ!$A:$A,0),3+L$7),"*","")) | M11: =IF($A11<>"",IFERROR(IF(SUBSTITUTE(D11,",",".")<>SUBSTITUTE(SUBSTITUTE(I11,",","."),"∞","oo"),1,""),"!"),"") | N11: =IF($A11<>"",IFERROR(IF(SUBSTITUTE(E11,",",".")<>SUBSTITUTE(SUBSTITUTE(J11,",","."),"∞","oo"),1,""),"!"),"") | O11: =IF($A11<>"",IFERROR(IF(SUBSTITUTE(F11,",",".")<>SUBSTITUTE(SUBSTITUTE(K11,",","."),"∞","oo"),1,""),"!"),"") | P11: =IF($A11<>"",IFERROR(IF(SUBSTITUTE(G11,",",".")<>SUBSTITUTE(SUBSTITUTE(L11,",","."),"∞","oo"),1,""),"!"),"")
A12: 0x2000016769F4 | B12: Изм 1ф_2 | C12: Выведено_x000D_ Введено | D12: Выведено | H12: Однофазное измерение, группа измерений 2 | I12: =TRIM(SUBSTITUTE(INDEX([1]ТУ!$A:$G,MATCH($A12,[1]ТУ!$A:$A,0),3+I$7),"*","")) -> Выведено | J12: =TRIM(SUBSTITUTE(INDEX([1]ТУ!$A:$G,MATCH($A12,[1]ТУ!$A:$A,0),3+J$7),"*","")) | K12: =TRIM(SUBSTITUTE(INDEX([1]ТУ!$A:$G,MATCH($A12,[1]ТУ!$A:$A,0),3+K$7),"*","")) | L12: =TRIM(SUBSTITUTE(INDEX([1]ТУ!$A:$G,MATCH($A12,[1]ТУ!$A:$A,0),3+L$7),"*","")) | M12: =IF($A12<>"",IFERROR(IF(SUBSTITUTE(D12,",",".")<>SUBSTITUTE(SUBSTITUTE(I12,",","."),"∞","oo"),1,""),"!"),"") | N12: =IF($A12<>"",IFERROR(IF(SUBSTITUTE(E12,",",".")<>SUBSTITUTE(SUBSTITUTE(J12,",","."),"∞","oo"),1,""),"!"),"") | O12: =IF($A12<>"",IFERROR(IF(SUBSTITUTE(F12,",",".")<>SUBSTITUTE(SUBSTITUTE(K12,",","."),"∞","oo"),1,""),"!"),"") | P12: =IF($A12<>"",IFERROR(IF(SUBSTITUTE(G12,",",".")<>SUBSTITUTE(SUBSTITUTE(L12,",","."),"∞","oo"),1,""),"!"),"")
A13: 0x2000016769F5 | B13: Изм 1ф_3 | C13: Выведено_x000D_ Введено | D13: Выведено | H13: Однофазное измерение, группа измерений 3 | I13: =TRIM(SUBSTITUTE(INDEX([1]ТУ!$A:$G,MATCH($A13,[1]ТУ!$A:$A,0),3+I$7),"*","")) -> Выведено | J13: =TRIM(SUBSTITUTE(INDEX([1]ТУ!$A:$G,MATCH($A13,[1]ТУ!$A:$A,0),3+J$7),"*","")) | K13: =TRIM(SUBSTITUTE(INDEX([1]ТУ!$A:$G,MATCH($A13,[1]ТУ!$A:$A,0),3+K$7),"*","")) | L13: =TRIM(SUBSTITUTE(INDEX([1]ТУ!$A:$G,MATCH($A13,[1]ТУ!$A:$A,0),3+L$7),"*","")) | M13: =IF($A13<>"",IFERROR(IF(SUBSTITUTE(D13,",",".")<>SUBSTITUTE(SUBSTITUTE(I13,",","."),"∞","oo"),1,""),"!"),"") | N13: =IF($A13<>"",IFERROR(IF(SUBSTITUTE(E13,",",".")<>SUBSTITUTE(SUBSTITUTE(J13,",","."),"∞","oo"),1,""),"!"),"") | O13: =IF($A13<>"",IFERROR(IF(SUBSTITUTE(F13,",",".")<>SUBSTITUTE(SUBSTITUTE(K13,",","."),"∞","oo"),1,""),"!"),"") | P13: =IF($A13<>"",IFERROR(IF(SUBSTITUTE(G13,",",".")<>SUBSTITUTE(SUBSTITUTE(L13,",","."),"∞","oo"),1,""),"!"),"")
A14: 0x2000016769F6 | B14: Изм 3ф_1 | C14: Выведено_x000D_ Введено | D14: Введено | H14: Трехфазное измерение, группа измерений 1 | I14: =TRIM(SUBSTITUTE(INDEX([1]ТУ!$A:$G,MATCH($A14,[1]ТУ!$A:$A,0),3+I$7),"*","")) -> Введено | J14: =TRIM(SUBSTITUTE(INDEX([1]ТУ!$A:$G,MATCH($A14,[1]ТУ!$A:$A,0),3+J$7),"*","")) | K14: =TRIM(SUBSTITUTE(INDEX([1]ТУ!$A:$G,MATCH($A14,[1]ТУ!$A:$A,0),3+K$7),"*","")) | L14: =TRIM(SUBSTITUTE(INDEX([1]ТУ!$A:$G,MATCH($A14,[1]ТУ!$A:$A,0),3+L$7),"*","")) | M14: =IF($A14<>"",IFERROR(IF(SUBSTITUTE(D14,",",".")<>SUBSTITUTE(SUBSTITUTE(I14,",","."),"∞","oo"),1,""),"!"),"") | N14: =IF($A14<>"",IFERROR(IF(SUBSTITUTE(E14,",",".")<>SUBSTITUTE(SUBSTITUTE(J14,",","."),"∞","oo"),1,""),"!"),"") | O14: =IF($A14<>"",IFERROR(IF(SUBSTITUTE(F14,",",".")<>SUBSTITUTE(SUBSTITUTE(K14,",","."),"∞","oo"),1,""),"!"),"") | P14: =IF($A14<>"",IFERROR(IF(SUBSTITUTE(G14,",",".")<>SUBSTITUTE(SUBSTITUTE(L14,",","."),"∞","oo"),1,""),"!"),"")
A15: 0x2000016769F7 | B15: Изм по сх.Арона | C15: Выведено_x000D_ Введено | D15: Выведено | H15: Измер по схем.2Ваттметров,группа измер.1 | I15: =TRIM(SUBSTITUTE(INDEX([1]ТУ!$A:$G,MATCH($A15,[1]ТУ!$A:$A,0),3+I$7),"*","")) -> Выведено | J15: =TRIM(SUBSTITUTE(INDEX([1]ТУ!$A:$G,MATCH($A15,[1]ТУ!$A:$A,0),3+J$7),"*","")) | K15: =TRIM(SUBSTITUTE(INDEX([1]ТУ!$A:$G,MATCH($A15,[1]ТУ!$A:$A,0),3+K$7),"*","")) | L15: =TRIM(SUBSTITUTE(INDEX([1]ТУ!$A:$G,MATCH($A15,[1]ТУ!$A:$A,0),3+L$7),"*","")) | M15: =IF($A15<>"",IFERROR(IF(SUBSTITUTE(D15,",",".")<>SUBSTITUTE(SUBSTITUTE(I15,",","."),"∞","oo"),1,""),"!"),"") | N15: =IF($A15<>"",IFERROR(IF(SUBSTITUTE(E15,",",".")<>SUBSTITUTE(SUBSTITUTE(J15,",","."),"∞","oo"),1,""),"!"),"") | O15: =IF($A15<>"",IFERROR(IF(SUBSTITUTE(F15,",",".")<>SUBSTITUTE(SUBSTITUTE(K15,",","."),"∞","oo"),1,""),"!"),"") | P15: =IF($A15<>"",IFERROR(IF(SUBSTITUTE(G15,",",".")<>SUBSTITUTE(SUBSTITUTE(L15,",","."),"∞","oo"),1,""),"!"),"")
A16: 0x2000016769DD | B16: ФункцСинхрон 1 | C16: Выведено_x000D_ Введено | D16: Выведено | H16: Функция синхронизации 1 | I16: =TRIM(SUBSTITUTE(INDEX([1]ТУ!$A:$G,MATCH($A16,[1]ТУ!$A:$A,0),3+I$7),"*","")) -> Выведено | J16: =TRIM(SUBSTITUTE(INDEX([1]ТУ!$A:$G,MATCH($A16,[1]ТУ!$A:$A,0),3+J$7),"*","")) | K16: =TRIM(SUBSTITUTE(INDEX([1]ТУ!$A:$G,MATCH($A16,[1]ТУ!$A:$A,0),3+K$7),"*","")) | L16: =TRIM(SUBSTITUTE(INDEX([1]ТУ!$A:$G,MATCH($A16,[1]ТУ!$A:$A,0),3+L$7),"*","")) | M16: =IF($A16<>"",IFERROR(IF(SUBSTITUTE(D16,",",".")<>SUBSTITUTE(SUBSTITUTE(I16,",","."),"∞","oo"),1,""),"!"),"") | N16: =IF($A16<>"",IFERROR(IF(SUBSTITUTE(E16,",",".")<>SUBSTITUTE(SUBSTITUTE(J16,",","."),"∞","oo"),1,""),"!"),"") | O16: =IF($A16<>"",IFERROR(IF(SUBSTITUTE(F16,",",".")<>SUBSTITUTE(SUBSTITUTE(K16,",","."),"∞","oo"),1,""),"!"),"") | P16: =IF($A16<>"",IFERROR(IF(SUBSTITUTE(G16,",",".")<>SUBSTITUTE(SUBSTITUTE(L16,",","."),"∞","oo"),1,""),"!"),"")
A17: 0x2000016769DE | B17: ФункцСинхрон 2 | C17: Выведено_x000D_ Введено | D17: Выведено | H17: Функция синхронизации 2 | I17: =TRIM(SUBSTITUTE(INDEX([1]ТУ!$A:$G,MATCH($A17,[1]ТУ!$A:$A,0),3+I$7),"*","")) -> Выведено | J17: =TRIM(SUBSTITUTE(INDEX([1]ТУ!$A:$G,MATCH($A17,[1]ТУ!$A:$A,0),3+J$7),"*","")) | K17: =TRIM(SUBSTITUTE(INDEX([1]ТУ!$A:$G,MATCH($A17,[1]ТУ!$A:$A,0),3+K$7),"*","")) | L17: =TRIM(SUBSTITUTE(INDEX([1]ТУ!$A:$G,MATCH($A17,[1]ТУ!$A:$A,0),3+L$7),"*","")) | M17: =IF($A17<>"",IFERROR(IF(SUBSTITUTE(D17,",",".")<>SUBSTITUTE(SUBSTITUTE(I17,",","."),"∞","oo"),1,""),"!"),"") | N17: =IF($A17<>"",IFERROR(IF(SUBSTITUTE(E17,",",".")<>SUBSTITUTE(SUBSTITUTE(J17,",","."),"∞","oo"),1,""),"!"),"") | O17: =IF($A17<>"",IFERROR(IF(SUBSTITUTE(F17,",",".")<>SUBSTITUTE(SUBSTITUTE(K17,",","."),"∞","oo"),1,""),"!"),"") | P17: =IF($A17<>"",IFERROR(IF(SUBSTITUTE(G17,",",".")<>SUBSTITUTE(SUBSTITUTE(L17,",","."),"∞","oo"),1,""),"!"),"")
A18: 0x2000016769DF | B18: ФункцСинхрон 3 | C18: Выведено_x000D_ Введено | D18: Выведено | H18: Функция синхронизации 3 | I18: =TRIM(SUBSTITUTE(INDEX([1]ТУ!$A:$G,MATCH($A18,[1]ТУ!$A:$A,0),3+I$7),"*","")) -> Выведено | J18: =TRIM(SUBSTITUTE(INDEX([1]ТУ!$A:$G,MATCH($A18,[1]ТУ!$A:$A,0),3+J$7),"*","")) | K18: =TRIM(SUBSTITUTE(INDEX([1]ТУ!$A:$G,MATCH($A18,[1]ТУ!$A:$A,0),3+K$7),"*","")) | L18: =TRIM(SUBSTITUTE(INDEX([1]ТУ!$A:$G,MATCH($A18,[1]ТУ!$A:$A,0),3+L$7),"*","")) | M18: =IF($A18<>"",IFERROR(IF(SUBSTITUTE(D18,",",".")<>SUBSTITUTE(SUBSTITUTE(I18,",","."),"∞","oo"),1,""),"!"),"") | N18: =IF($A18<>"",IFERROR(IF(SUBSTITUTE(E18,",",".")<>SUBSTITUTE(SUBSTITUTE(J18,",","."),"∞","oo"),1,""),"!"),"") | O18: =IF($A18<>"",IFERROR(IF(SUBSTITUTE(F18,",",".")<>SUBSTITUTE(SUBSTITUTE(K18,",","."),"∞","oo"),1,""),"!"),"") | P18: =IF($A18<>"",IFERROR(IF(SUBSTITUTE(G18,",",".")<>SUBSTITUTE(SUBSTITUTE(L18,",","."),"∞","oo"),1,""),"!"),"")
A19: 0x2000016769E0 | B19: ФункцСинхрон 4 | C19: Выведено_x000D_ Введено | D19: Выведено | H19: Функция синхронизации 4 | I19: =TRIM(SUBSTITUTE(INDEX([1]ТУ!$A:$G,MATCH($A19,[1]ТУ!$A:$A,0),3+I$7),"*","")) -> Выведено | J19: =TRIM(SUBSTITUTE(INDEX([1]ТУ!$A:$G,MATCH($A19,[1]ТУ!$A:$A,0),3+J$7),"*","")) | K19: =TRIM(SUBSTITUTE(INDEX([1]ТУ!$A:$G,MATCH($A19,[1]ТУ!$A:$A,0),3+K$7),"*","")) | L19: =TRIM(SUBSTITUTE(INDEX([1]ТУ!$A:$G,MATCH($A19,[1]ТУ!$A:$A,0),3+L$7),"*","")) | M19: =IF($A19<>"",IFERROR(IF(SUBSTITUTE(D19,",",".")<>SUBSTITUTE(SUBSTITUTE(I19,",","."),"∞","oo"),1,""),"!"),"") | N19: =IF($A19<>"",IFERROR(IF(SUBSTITUTE(E19,",",".")<>SUBSTITUTE(SUBSTITUTE(J19,",","."),"∞","oo"),1,""),"!"),"") | O19: =IF($A19<>"",IFERROR(IF(SUBSTITUTE(F19,",",".")<>SUBSTITUTE(SUBSTITUTE(K19,",","."),"∞","oo"),1,""),"!"),"") | P19: =IF($A19<>"",IFERROR(IF(SUBSTITUTE(G19,",",".")<>SUBSTITUTE(SUBSTITUTE(L19,",","."),"∞","oo"),1,""),"!"),"")
... A27: 0139 | B27: УРОВ | C27: Выведено_x000D_ Введено | D27: Введено | H27: Устр. резерв. отказа выключателя (УРОВ) | I27: =TRIM(SUBSTITUTE(INDEX([1]ТУ!$A:$G,MATCH($A27,[1]ТУ!$A:$A,0),3+I$7),"*","")) -> Введено | J27: =TRIM(SUBSTITUTE(INDEX([1]ТУ!$A:$G,MATCH($A27,[1]ТУ!$A:$A,0),3+J$7),"*","")) | K27: =TRIM(SUBSTITUTE(INDEX([1]ТУ!$A:$G,MATCH($A27,[1]ТУ!$A:$A,0),3+K$7),"*","")) | L27: =TRIM(SUBSTITUTE(INDEX([1]ТУ!$A:$G,MATCH($A27,[1]ТУ!$A:$A,0),3+L$7),"*","")) | M27: =IF($A27<>"",IFERROR(IF(SUBSTITUTE(D27,",",".")<>SUBSTITUTE(SUBSTITUTE(I27,",","."),"∞","oo"),1,""),"!"),"") | N27: =IF($A27<>"",IFERROR(IF(SUBSTITUTE(E27,",",".")<>SUBSTITUTE(SUBSTITUTE(J27,",","."),"∞","oo"),1,""),"!"),"") | O27: =IF($A27<>"",IFERROR(IF(SUBSTITUTE(F27,",",".")<>SUBSTITUTE(SUBSTITUTE(K27,",","."),"∞","oo"),1,""),"!"),"") | P27: =IF($A27<>"",IFERROR(IF(SUBSTITUTE(G27,",",".")<>SUBSTITUTE(SUBSTITUTE(L27,",","."),"∞","oo"),1,""),"!"),"")
A28: Общие установки утройства | I28: =TRIM(SUBSTITUTE(INDEX([1]ТУ!$A:$G,MATCH($A28,[1]ТУ!$A:$A,0),3+I$7),"*","")) -> #N/A | J28: =TRIM(SUBSTITUTE(INDEX([1]ТУ!$A:$G,MATCH($A28,[1]ТУ!$A:$A,0),3+J$7),"*","")) -> #N/A | K28: =TRIM(SUBSTITUTE(INDEX([1]ТУ!$A:$G,MATCH($A28,[1]ТУ!$A:$A,0),3+K$7),"*","")) -> #N/A | L28: =TRIM(SUBSTITUTE(INDEX([1]ТУ!$A:$G,MATCH($A28,[1]ТУ!$A:$A,0),3+L$7),"*","")) -> #N/A | M28: =IF($A28<>"",IFERROR(IF(SUBSTITUTE(D28,",",".")<>SUBSTITUTE(SUBSTITUTE(I28,",","."),"∞","oo"),1,""),"!"),"") -> ! | N28: =IF($A28<>"",IFERROR(IF(SUBSTITUTE(E28,",",".")<>SUBSTITUTE(SUBSTITUTE(J28,",","."),"∞","oo"),1,""),"!"),"") -> ! | O28: =IF($A28<>"",IFERROR(IF(SUBSTITUTE(F28,",",".")<>SUBSTITUTE(SUBSTITUTE(K28,",","."),"∞","oo"),1,""),"!"),"") -> ! | P28: =IF($A28<>"",IFERROR(IF(SUBSTITUTE(G28,",",".")<>SUBSTITUTE(SUBSTITUTE(L28,",","."),"∞","oo"),1,""),"!"),"") -> !
A29: Общее | I29: =TRIM(SUBSTITUTE(INDEX([1]ТУ!$A:$G,MATCH($A29,[1]ТУ!$A:$A,0),3+I$7),"*","")) | J29: =TRIM(SUBSTITUTE(INDEX([1]ТУ!$A:$G,MATCH($A29,[1]ТУ!$A:$A,0),3+J$7),"*","")) | K29: =TRIM(SUBSTITUTE(INDEX([1]ТУ!$A:$G,MATCH($A29,[1]ТУ!$A:$A,0),3+K$7),"*","")) | L29: =TRIM(SUBSTITUTE(INDEX([1]ТУ!$A:$G,MATCH($A29,[1]ТУ!$A:$A,0),3+L$7),"*","")) | M29: =IF($A29<>"",IFERROR(IF(SUBSTITUTE(D29,",",".")<>SUBSTITUTE(SUBSTITUTE(I29,",","."),"∞","oo"),1,""),"!"),"") | N29: =IF($A29<>"",IFERROR(IF(SUBSTITUTE(E29,",",".")<>SUBSTITUTE(SUBSTITUTE(J29,",","."),"∞","oo"),1,""),"!"),"") | O29: =IF($A29<>"",IFERROR(IF(SUBSTITUTE(F29,",",".")<>SUBSTITUTE(SUBSTITUTE(K29,",","."),"∞","oo"),1,""),"!"),"") | P29: =IF($A29<>"",IFERROR(IF(SUBSTITUTE(G29,",",".")<>SUBSTITUTE(SUBSTITUTE(L29,",","."),"∞","oo"),1,""),"!"),"")
A30: Адрес | B30: Параметр | C30: Значение/диапазон/шаг | D30: Задаваемый параметр | H30: Комментарий | I30: =TRIM(SUBSTITUTE(INDEX([1]ТУ!$A:$G,MATCH($A30,[1]ТУ!$A:$A,0),3+I$7),"*","")) -> Задаваемый параметр | J30: =TRIM(SUBSTITUTE(INDEX([1]ТУ!$A:$G,MATCH($A30,[1]ТУ!$A:$A,0),3+J$7),"*","")) | K30: =TRIM(SUBSTITUTE(INDEX([1]ТУ!$A:$G,MATCH($A30,[1]ТУ!$A:$A,0),3+K$7),"*","")) | L30: =TRIM(SUBSTITUTE(INDEX([1]ТУ!$A:$G,MATCH($A30,[1]ТУ!$A:$A,0),3+L$7),"*","")) | M30: =IF($A30<>"",IFERROR(IF(SUBSTITUTE(D30,",",".")<>SUBSTITUTE(SUBSTITUTE(I30,",","."),"∞","oo"),1,""),"!"),"") | N30: =IF($A30<>"",IFERROR(IF(SUBSTITUTE(E30,",",".")<>SUBSTITUTE(SUBSTITUTE(J30,",","."),"∞","oo"),1,""),"!"),"") | O30: =IF($A30<>"",IFERROR(IF(SUBSTITUTE(F30,",",".")<>SUBSTITUTE(SUBSTITUTE(K30,",","."),"∞","oo"),1,""),"!"),"") | P30: =IF($A30<>"",IFERROR(IF(SUBSTITUTE(G30,",",".")<>SUBSTITUTE(SUBSTITUTE(L30,",","."),"∞","oo"),1,""),"!"),"")
I31: =TRIM(SUBSTITUTE(INDEX([1]ТУ!$A:$G,MATCH($A31,[1]ТУ!$A:$A,0),3+I$7),"*","")) -> #N/A | J31: =TRIM(SUBSTITUTE(INDEX([1]ТУ!$A:$G,MATCH($A31,[1]ТУ!$A:$A,0),3+J$7),"*","")) -> #N/A | K31: =TRIM(SUBSTITUTE(INDEX([1]ТУ!$A:$G,MATCH($A31,[1]ТУ!$A:$A,0),3+K$7),"*","")) -> #N/A | L31: =TRIM(SUBSTITUTE(INDEX([1]ТУ!$A:$G,MATCH($A31,[1]ТУ!$A:$A,0),3+L$7),"*","")) -> #N/A | M31: =IF($A31<>"",IFERROR(IF(SUBSTITUTE(D31,",",".")<>SUBSTITUTE(SUBSTITUTE(I31,",","."),"∞","oo"),1,""),"!"),"") | N31: =IF($A31<>"",IFERROR(IF(SUBSTITUTE(E31,",",".")<>SUBSTITUTE(SUBSTITUTE(J31,",","."),"∞","oo"),1,""),"!"),"") | O31: =IF($A31<>"",IFERROR(IF(SUBSTITUTE(F31,",",".")<>SUBSTITUTE(SUBSTITUTE(K31,",","."),"∞","oo"),1,""),"!"),"") | P31: =IF($A31<>"",IFERROR(IF(SUBSTITUTE(G31,",",".")<>SUBSTITUTE(SUBSTITUTE(L31,",","."),"∞","oo"),1,""),"!"),"")
A32: 0401 | B32: Время подсветки | C32: 1 … 60 мин | D32: 10 мин | H32: Время подсветки | I32: =TRIM(SUBSTITUTE(INDEX([1]ТУ!$A:$G,MATCH($A32,[1]ТУ!$A:$A,0),3+I$7),"*","")) -> #N/A | J32: =TRIM(SUBSTITUTE(INDEX([1]ТУ!$A:$G,MATCH($A32,[1]ТУ!$A:$A,0),3+J$7),"*","")) -> #N/A | K32: =TRIM(SUBSTITUTE(INDEX([1]ТУ!$A:$G,MATCH($A32,[1]ТУ!$A:$A,0),3+K$7),"*","")) -> #N/A | L32: =TRIM(SUBSTITUTE(INDEX([1]ТУ!$A:$G,MATCH($A32,[1]ТУ!$A:$A,0),3+L$7),"*","")) -> #N/A | M32: =IF($A32<>"",IFERROR(IF(SUBSTITUTE(D32,",",".")<>SUBSTITUTE(SUBSTITUTE(I32,",","."),"∞","oo"),1,""),"!"),"") -> ! | N32: =IF($A32<>"",IFERROR(IF(SUBSTITUTE(E32,",",".")<>SUBSTITUTE(SUBSTITUTE(J32,",","."),"∞","oo"),1,""),"!"),"") -> ! | O32: =IF($A32<>"",IFERROR(IF(SUBSTITUTE(F32,",",".")<>SUBSTITUTE(SUBSTITUTE(K32,",","."),"∞","oo"),1,""),"!"),"") -> ! | P32: =IF($A32<>"",IFERROR(IF(SUBSTITUTE(G32,",",".")<>SUBSTITUTE(SUBSTITUTE(L32,",","."),"∞","oo"),1,""),"!"),"") -> !
A33: 0402 | B33: DIGSI задн.порт | C33: Выведено_x000D_ Порт С_x000D_ Порт D | D33: Порт D | H33: Задний порт для DIGSI | I33: =TRIM(SUBSTITUTE(INDEX([1]ТУ!$A:$G,MATCH($A33,[1]ТУ!$A:$A,0),3+I$7),"*","")) -> #N/A | J33: =TRIM(SUBSTITUTE(INDEX([1]ТУ!$A:$G,MATCH($A33,[1]ТУ!$A:$A,0),3+J$7),"*","")) -> #N/A | K33: =TRIM(SUBSTITUTE(INDEX([1]ТУ!$A:$G,MATCH($A33,[1]ТУ!$A:$A,0),3+K$7),"*","")) -> #N/A | L33: =TRIM(SUBSTITUTE(INDEX([1]ТУ!$A:$G,MATCH($A33,[1]ТУ!$A:$A,0),3+L$7),"*","")) -> #N/A | M33: =IF($A33<>"",IFERROR(IF(SUBSTITUTE(D33,",",".")<>SUBSTITUTE(SUBSTITUTE(I33,",","."),"∞","oo"),1,""),"!"),"") -> ! | N33: =IF($A33<>"",IFERROR(IF(SUBSTITUTE(E33,",",".")<>SUBSTITUTE(SUBSTITUTE(J33,",","."),"∞","oo"),1,""),"!"),"") -> ! | O33: =IF($A33<>"",IFERROR(IF(SUBSTITUTE(F33,",",".")<>SUBSTITUTE(SUBSTITUTE(K33,",","."),"∞","oo"),1,""),"!"),"") -> ! | P33: =IF($A33<>"",IFERROR(IF(SUBSTITUTE(G33,",",".")<>SUBSTITUTE(SUBSTITUTE(L33,",","."),"∞","oo"),1,""),"!"),"") -> !
A34: 0407 | B34: ИндПовр СД/Дсп | C34: Отображение сообщений при каждом пуске_x000D_ Отображение сообщений только при откл. | D34: Отображение сообщений при каждом пуске | H34: Индикация повреждений: светодиод/дисплей | I34: =TRIM(SUBSTITUTE(INDEX([1]ТУ!$A:$G,MATCH($A34,[1]ТУ!$A:$A,0),3+I$7),"*","")) -> #N/A | J34: =TRIM(SUBSTITUTE(INDEX([1]ТУ!$A:$G,MATCH($A34,[1]ТУ!$A:$A,0),3+J$7),"*","")) -> #N/A | K34: =TRIM(SUBSTITUTE(INDEX([1]ТУ!$A:$G,MATCH($A34,[1]ТУ!$A:$A,0),3+K$7),"*","")) -> #N/A | L34: =TRIM(SUBSTITUTE(INDEX([1]ТУ!$A:$G,MATCH($A34,[1]ТУ!$A:$A,0),3+L$7),"*","")) -> #N/A | M34: =IF($A34<>"",IFERROR(IF(SUBSTITUTE(D34,",",".")<>SUBSTITUTE(SUBSTITUTE(I34,",","."),"∞","oo"),1,""),"!"),"") -> ! | N34: =IF($A34<>"",IFERROR(IF(SUBSTITUTE(E34,",",".")<>SUBSTITUTE(SUBSTITUTE(J34,",","."),"∞","oo"),1,""),"!"),"") -> ! | O34: =IF($A34<>"",IFERROR(IF(SUBSTITUTE(F34,",",".")<>SUBSTITUTE(SUBSTITUTE(K34,",","."),"∞","oo"),1,""),"!"),"") -> ! | P34: =IF($A34<>"",IFERROR(IF(SUBSTITUTE(G34,",",".")<>SUBSTITUTE(SUBSTITUTE(L34,",","."),"∞","oo"),1,""),"!"),"") -> !
A35: 0408 | B35: СпонтОтобрПовр | C35: НЕТ_x000D_ ДА | D35: НЕТ | H35: Спонтанное отображ.сообщений о поврежд. | I35: =TRIM(SUBSTITUTE(INDEX([1]ТУ!$A:$G,MATCH($A35,[1]ТУ!$A:$A,0),3+I$7),"*","")) -> #N/A | J35: =TRIM(SUBSTITUTE(INDEX([1]ТУ!$A:$G,MATCH($A35,[1]ТУ!$A:$A,0),3+J$7),"*","")) -> #N/A | K35: =TRIM(SUBSTITUTE(INDEX([1]ТУ!$A:$G,MATCH($A35,[1]ТУ!$A:$A,0),3+K$7),"*","")) -> #N/A | L35: =TRIM(SUBSTITUTE(INDEX([1]ТУ!$A:$G,MATCH($A35,[1]ТУ!$A:$A,0),3+L$7),"*","")) -> #N/A | M35: =IF($A35<>"",IFERROR(IF(SUBSTITUTE(D35,",",".")<>SUBSTITUTE(SUBSTITUTE(I35,",","."),"∞","oo"),1,""),"!"),"") -> ! | N35: =IF($A35<>"",IFERROR(IF(SUBSTITUTE(E35,",",".")<>SUBSTITUTE(SUBSTITUTE(J35,",","."),"∞","oo"),1,""),"!"),"") -> ! | O35: =IF($A35<>"",IFERROR(IF(SUBSTITUTE(F35,",",".")<>SUBSTITUTE(SUBSTITUTE(K35,",","."),"∞","oo"),1,""),"!"),"") -> ! | P35: =IF($A35<>"",IFERROR(IF(SUBSTITUTE(G35,",",".")<>SUBSTITUTE(SUBSTITUTE(L35,",","."),"∞","oo"),1,""),"!"),"") -> !
A36: Данные энергосистемы 1 | I36: =TRIM(SUBSTITUTE(INDEX([1]ТУ!$A:$G,MATCH($A36,[1]ТУ!$A:$A,0),3+I$7),"*","")) | J36: =TRIM(SUBSTITUTE(INDEX([1]ТУ!$A:$G,MATCH($A36,[1]ТУ!$A:$A,0),3+J$7),"*","")) | K36: =TRIM(SUBSTITUTE(INDEX([1]ТУ!$A:$G,MATCH($A36,[1]ТУ!$A:$A,0),3+K$7),"*","")) | L36: =TRIM(SUBSTITUTE(INDEX([1]ТУ!$A:$G,MATCH($A36,[1]ТУ!$A:$A,0),3+L$7),"*","")) | M36: =IF($A36<>"",IFERROR(IF(SUBSTITUTE(D36,",",".")<>SUBSTITUTE(SUBSTITUTE(I36,",","."),"∞","oo"),1,""),"!"),"") | N36: =IF($A36<>"",IFERROR(IF(SUBSTITUTE(E36,",",".")<>SUBSTITUTE(SUBSTITUTE(J36,",","."),"∞","oo"),1,""),"!"),"") | O36: =IF($A36<>"",IFERROR(IF(SUBSTITUTE(F36,",",".")<>SUBSTITUTE(SUBSTITUTE(K36,",","."),"∞","oo"),1,""),"!"),"") | P36: =IF($A36<>"",IFERROR(IF(SUBSTITUTE(G36,",",".")<>SUBSTITUTE(SUBSTITUTE(L36,",","."),"∞","oo"),1,""),"!"),"")
A37: Параметры сети | I37: =TRIM(SUBSTITUTE(INDEX([1]ТУ!$A:$G,MATCH($A37,[1]ТУ!$A:$A,0),3+I$7),"*","")) | J37: =TRIM(SUBSTITUTE(INDEX([1]ТУ!$A:$G,MATCH($A37,[1]ТУ!$A:$A,0),3+J$7),"*","")) | K37: =TRIM(SUBSTITUTE(INDEX([1]ТУ!$A:$G,MATCH($A37,[1]ТУ!$A:$A,0),3+K$7),"*","")) | L37: =TRIM(SUBSTITUTE(INDEX([1]ТУ!$A:$G,MATCH($A37,[1]ТУ!$A:$A,0),3+L$7),"*","")) | M37: =IF($A37<>"",IFERROR(IF(SUBSTITUTE(D37,",",".")<>SUBSTITUTE(SUBSTITUTE(I37,",","."),"∞","oo"),1,""),"!"),"") | N37: =IF($A37<>"",IFERROR(IF(SUBSTITUTE(E37,",",".")<>SUBSTITUTE(SUBSTITUTE(J37,",","."),"∞","oo"),1,""),"!"),"") | O37: =IF($A37<>"",IFERROR(IF(SUBSTITUTE(F37,",",".")<>SUBSTITUTE(SUBSTITUTE(K37,",","."),"∞","oo"),1,""),"!"),"") | P37: =IF($A37<>"",IFERROR(IF(SUBSTITUTE(G37,",",".")<>SUBSTITUTE(SUBSTITUTE(L37,",","."),"∞","oo"),1,""),"!"),"")
A38: Адрес | B38: Параметр | C38: Значение/диапазон/шаг | D38: Задаваемый параметр | H38: Комментарий | I38: =TRIM(SUBSTITUTE(INDEX([1]ТУ!$A:$G,MATCH($A38,[1]ТУ!$A:$A,0),3+I$7),"*","")) -> Задаваемый параметр | J38: =TRIM(SUBSTITUTE(INDEX([1]ТУ!$A:$G,MATCH($A38,[1]ТУ!$A:$A,0),3+J$7),"*","")) | K38: =TRIM(SUBSTITUTE(INDEX([1]ТУ!$A:$G,MATCH($A38,[1]ТУ!$A:$A,0),3+K$7),"*","")) | L38: =TRIM(SUBSTITUTE(INDEX([1]ТУ!$A:$G,MATCH($A38,[1]ТУ!$A:$A,0),3+L$7),"*","")) | M38: =IF($A38<>"",IFERROR(IF(SUBSTITUTE(D38,",",".")<>SUBSTITUTE(SUBSTITUTE(I38,",","."),"∞","oo"),1,""),"!"),"") | N38: =IF($A38<>"",IFERROR(IF(SUBSTITUTE(E38,",",".")<>SUBSTITUTE(SUBSTITUTE(J38,",","."),"∞","oo"),1,""),"!"),"") | O38: =IF($A38<>"",IFERROR(IF(SUBSTITUTE(F38,",",".")<>SUBSTITUTE(SUBSTITUTE(K38,",","."),"∞","oo"),1,""),"!"),"") | P38: =IF($A38<>"",IFERROR(IF(SUBSTITUTE(G38,",",".")<>SUBSTITUTE(SUBSTITUTE(L38,",","."),"∞","oo"),1,""),"!"),"")
I39: =TRIM(SUBSTITUTE(INDEX([1]ТУ!$A:$G,MATCH($A39,[1]ТУ!$A:$A,0),3+I$7),"*","")) -> #N/A | J39: =TRIM(SUBSTITUTE(INDEX([1]ТУ!$A:$G,MATCH($A39,[1]ТУ!$A:$A,0),3+J$7),"*","")) -> #N/A | K39: =TRIM(SUBSTITUTE(INDEX([1]ТУ!$A:$G,MATCH($A39,[1]ТУ!$A:$A,0),3+K$7),"*","")) -> #N/A | L39: =TRIM(SUBSTITUTE(INDEX([1]ТУ!$A:$G,MATCH($A39,[1]ТУ!$A:$A,0),3+L$7),"*","")) -> #N/A | M39: =IF($A39<>"",IFERROR(IF(SUBSTITUTE(D39,",",".")<>SUBSTITUTE(SUBSTITUTE(I39,",","."),"∞","oo"),1,""),"!"),"") | N39: =IF($A39<>"",IFERROR(IF(SUBSTITUTE(E39,",",".")<>SUBSTITUTE(SUBSTITUTE(J39,",","."),"∞","oo"),1,""),"!"),"") | O39: =IF($A39<>"",IFERROR(IF(SUBSTITUTE(F39,",",".")<>SUBSTITUTE(SUBSTITUTE(K39,",","."),"∞","oo"),1,""),"!"),"") | P39: =IF($A39<>"",IFERROR(IF(SUBSTITUTE(G39,",",".")<>SUBSTITUTE(SUBSTITUTE(L39,",","."),"∞","oo"),1,""),"!"),"")
A40: 0203 | B40: Uном Первич | C40: 1.0 … 1200.0 кВ | D40: 220.0 кВ | H40: Первичное номинальное напряжение | I40: =TRIM(SUBSTITUTE(INDEX([1]ТУ!$A:$G,MATCH($A40,[1]ТУ!$A:$A,0),3+I$7),"*","")) -> 220 кВ | J40: =TRIM(SUBSTITUTE(INDEX([1]ТУ!$A:$G,MATCH($A40,[1]ТУ!$A:$A,0),3+J$7),"*","")) | K40: =TRIM(SUBSTITUTE(INDEX([1]ТУ!$A:$G,MATCH($A40,[1]ТУ!$A:$A,0),3+K$7),"*","")) | L40: =TRIM(SUBSTITUTE(INDEX([1]ТУ!$A:$G,MATCH($A40,[1]ТУ!$A:$A,0),3+L$7),"*","")) | M40: =IF($A40<>"",IFERROR(IF(SUBSTITUTE(D40,",",".")<>SUBSTITUTE(SUBSTITUTE(I40,",","."),"∞","oo"),1,""),"!"),"") -> 1 | N40: =IF($A40<>"",IFERROR(IF(SUBSTITUTE(E40,",",".")<>SUBSTITUTE(SUBSTITUTE(J40,",","."),"∞","oo"),1,""),"!"),"") | O40: =IF($A40<>"",IFERROR(IF(SUBSTITUTE(F40,",",".")<>SUBSTITUTE(SUBSTITUTE(K40,",","."),"∞","oo"),1,""),"!"),"") | P40: =IF($A40<>"",IFERROR(IF(SUBSTITUTE(G40,",",".")<>SUBSTITUTE(SUBSTITUTE(L40,",","."),"∞","oo"),1,""),"!"),"")
A41: 0204 | B41: Uном Вторич | C41: 80 … 125 В | D41: 100 В | H41: Вторичное номинальное напряжение | I41: =TRIM(SUBSTITUTE(INDEX([1]ТУ!$A:$G,MATCH($A41,[1]ТУ!$A:$A,0),3+I$7),"*","")) -> 100 В | J41: =TRIM(SUBSTITUTE(INDEX([1]ТУ!$A:$G,MATCH($A41,[1]ТУ!$A:$A,0),3+J$7),"*","")) | K41: =TRIM(SUBSTITUTE(INDEX([1]ТУ!$A:$G,MATCH($A41,[1]ТУ!$A:$A,0),3+K$7),"*","")) | L41: =TRIM(SUBSTITUTE(INDEX([1]ТУ!$A:$G,MATCH($A41,[1]ТУ!$A:$A,0),3+L$7),"*","")) | M41: =IF($A41<>"",IFERROR(IF(SUBSTITUTE(D41,",",".")<>SUBSTITUTE(SUBSTITUTE(I41,",","."),"∞","oo"),1,""),"!"),"") | N41: =IF($A41<>"",IFERROR(IF(SUBSTITUTE(E41,",",".")<>SUBSTITUTE(SUBSTITUTE(J41,",","."),"∞","oo"),1,""),"!"),"") | O41: =IF($A41<>"",IFERROR(IF(SUBSTITUTE(F41,",",".")<>SUBSTITUTE(SUBSTITUTE(K41,",","."),"∞","oo"),1,""),"!"),"") | P41: =IF($A41<>"",IFERROR(IF(SUBSTITUTE(G41,",",".")<>SUBSTITUTE(SUBSTITUTE(L41,",","."),"∞","oo"),1,""),"!"),"")
A42: 0205 | B42: Iном первич ТТ | C42: 10 … 5000 А | D42: 1000 А | H42: Первичный номинальный ток ТТ | I42: =TRIM(SUBSTITUTE(INDEX([1]ТУ!$A:$G,MATCH($A42,[1]ТУ!$A:$A,0),3+I$7),"*","")) -> 1000 А | J42: =TRIM(SUBSTITUTE(INDEX([1]ТУ!$A:$G,MATCH($A42,[1]ТУ!$A:$A,0),3+J$7),"*","")) | K42: =TRIM(SUBSTITUTE(INDEX([1]ТУ!$A:$G,MATCH($A42,[1]ТУ!$A:$A,0),3+K$7),"*","")) | L42: =TRIM(SUBSTITUTE(INDEX([1]ТУ!$A:$G,MATCH($A42,[1]ТУ!$A:$A,0),3+L$7),"*","")) | M42: =IF($A42<>"",IFERROR(IF(SUBSTITUTE(D42,",",".")<>SUBSTITUTE(SUBSTITUTE(I42,",","."),"∞","oo"),1,""),"!"),"") | N42: =IF($A42<>"",IFERROR(IF(SUBSTITUTE(E42,",",".")<>SUBSTITUTE(SUBSTITUTE(J42,",","."),"∞","oo"),1,""),"!"),"") | O42: =IF($A42<>"",IFERROR(IF(SUBSTITUTE(F42,",",".")<>SUBSTITUTE(SUBSTITUTE(K42,",","."),"∞","oo"),1,""),"!"),"") | P42: =IF($A42<>"",IFERROR(IF(SUBSTITUTE(G42,",",".")<>SUBSTITUTE(SUBSTITUTE(L42,",","."),"∞","oo"),1,""),"!"),"")
A43: 0206 | B43: Iном вротич ТТ | C43: 1А_x000D_ 5А | D43: 1А | H43: Вторичный номинальный ток ТТ | I43: =TRIM(SUBSTITUTE(INDEX([1]ТУ!$A:$G,MATCH($A43,[1]ТУ!$A:$A,0),3+I$7),"*","")) -> 1А | J43: =TRIM(SUBSTITUTE(INDEX([1]ТУ!$A:$G,MATCH($A43,[1]ТУ!$A:$A,0),3+J$7),"*","")) | K43: =TRIM(SUBSTITUTE(INDEX([1]ТУ!$A:$G,MATCH($A43,[1]ТУ!$A:$A,0),3+K$7),"*","")) | L43: =TRIM(SUBSTITUTE(INDEX([1]ТУ!$A:$G,MATCH($A43,[1]ТУ!$A:$A,0),3+L$7),"*","")) | M43: =IF($A43<>"",IFERROR(IF(SUBSTITUTE(D43,",",".")<>SUBSTITUTE(SUBSTITUTE(I43,",","."),"∞","oo"),1,""),"!"),"") | N43: =IF($A43<>"",IFERROR(IF(SUBSTITUTE(E43,",",".")<>SUBSTITUTE(SUBSTITUTE(J43,",","."),"∞","oo"),1,""),"!"),"") | O43: =IF($A43<>"",IFERROR(IF(SUBSTITUTE(F43,",",".")<>SUBSTITUTE(SUBSTITUTE(K43,",","."),"∞","oo"),1,""),"!"),"") | P43: =IF($A43<>"",IFERROR(IF(SUBSTITUTE(G43,",",".")<>SUBSTITUTE(SUBSTITUTE(L43,",","."),"∞","oo"),1,""),"!"),"")
A44: 0214 | B44: Номин Частота | C44: 50 Гц_x000D_ 60 Гц | D44: 50 Гц | H44: Номинальная частота | I44: =TRIM(SUBSTITUTE(INDEX([1]ТУ!$A:$G,MATCH($A44,[1]ТУ!$A:$A,0),3+I$7),"*","")) -> 50 Гц | J44: =TRIM(SUBSTITUTE(INDEX([1]ТУ!$A:$G,MATCH($A44,[1]ТУ!$A:$A,0),3+J$7),"*","")) | K44: =TRIM(SUBSTITUTE(INDEX([1]ТУ!$A:$G,MATCH($A44,[1]ТУ!$A:$A,0),3+K$7),"*","")) | L44: =TRIM(SUBSTITUTE(INDEX([1]ТУ!$A:$G,MATCH($A44,[1]ТУ!$A:$A,0),3+L$7),"*","")) | M44: =IF($A44<>"",IFERROR(IF(SUBSTITUTE(D44,",",".")<>SUBSTITUTE(SUBSTITUTE(I44,",","."),"∞","oo"),1,""),"!"),"") | N44: =IF($A44<>"",IFERROR(IF(SUBSTITUTE(E44,",",".")<>SUBSTITUTE(SUBSTITUTE(J44,",","."),"∞","oo"),1,""),"!"),"") | O44: =IF($A44<>"",IFERROR(IF(SUBSTITUTE(F44,",",".")<>SUBSTITUTE(SUBSTITUTE(K44,",","."),"∞","oo"),1,""),"!"),"") | P44: =IF($A44<>"",IFERROR(IF(SUBSTITUTE(G44,",",".")<>SUBSTITUTE(SUBSTITUTE(L44,",","."),"∞","oo"),1,""),"!"),"")
A45: Выключатель | I45: =TRIM(SUBSTITUTE(INDEX([1]ТУ!$A:$G,MATCH($A45,[1]ТУ!$A:$A,0),3+I$7),"*","")) | J45: =TRIM(SUBSTITUTE(INDEX([1]ТУ!$A:$G,MATCH($A45,[1]ТУ!$A:$A,0),3+J$7),"*","")) | K45: =TRIM(SUBSTITUTE(INDEX([1]ТУ!$A:$G,MATCH($A45,[1]ТУ!$A:$A,0),3+K$7),"*","")) | L45: =TRIM(SUBSTITUTE(INDEX([1]ТУ!$A:$G,MATCH($A45,[1]ТУ!$A:$A,0),3+L$7),"*","")) | M45: =IF($A45<>"",IFERROR(IF(SUBSTITUTE(D45,",",".")<>SUBSTITUTE(SUBSTITUTE(I45,",","."),"∞","oo"),1,""),"!"),"") | N45: =IF($A45<>"",IFERROR(IF(SUBSTITUTE(E45,",",".")<>SUBSTITUTE(SUBSTITUTE(J45,",","."),"∞","oo"),1,""),"!"),"") | O45: =IF($A45<>"",IFERROR(IF(SUBSTITUTE(F45,",",".")<>SUBSTITUTE(SUBSTITUTE(K45,",","."),"∞","oo"),1,""),"!"),"") | P45: =IF($A45<>"",IFERROR(IF(SUBSTITUTE(G45,",",".")<>SUBSTITUTE(SUBSTITUTE(L45,",","."),"∞","oo"),1,""),"!"),"")
A46: Адрес | B46: Параметр | C46: Значение/диапазон/шаг | D46: Задаваемый параметр | H46: Комментарий | I46: =TRIM(SUBSTITUTE(INDEX([1]ТУ!$A:$G,MATCH($A46,[1]ТУ!$A:$A,0),3+I$7),"*","")) -> Задаваемый параметр | J46: =TRIM(SUBSTITUTE(INDEX([1]ТУ!$A:$G,MATCH($A46,[1]ТУ!$A:$A,0),3+J$7),"*","")) | K46: =TRIM(SUBSTITUTE(INDEX([1]ТУ!$A:$G,MATCH($A46,[1]ТУ!$A:$A,0),3+K$7),"*","")) | L46: =TRIM(SUBSTITUTE(INDEX([1]ТУ!$A:$G,MATCH($A46,[1]ТУ!$A:$A,0),3+L$7),"*","")) | M46: =IF($A46<>"",IFERROR(IF(SUBSTITUTE(D46,",",".")<>SUBSTITUTE(SUBSTITUTE(I46,",","."),"∞","oo"),1,""),"!"),"") | N46: =IF($A46<>"",IFERROR(IF(SUBSTITUTE(E46,",",".")<>SUBSTITUTE(SUBSTITUTE(J46,",","."),"∞","oo"),1,""),"!"),"") | O46: =IF($A46<>"",IFERROR(IF(SUBSTITUTE(F46,",",".")<>SUBSTITUTE(SUBSTITUTE(K46,",","."),"∞","oo"),1,""),"!"),"") | P46: =IF($A46<>"",IFERROR(IF(SUBSTITUTE(G46,",",".")<>SUBSTITUTE(SUBSTITUTE(L46,",","."),"∞","oo"),1,""),"!"),"")
I47: =TRIM(SUBSTITUTE(INDEX([1]ТУ!$A:$G,MATCH($A47,[1]ТУ!$A:$A,0),3+I$7),"*","")) -> #N/A | J47: =TRIM(SUBSTITUTE(INDEX([1]ТУ!$A:$G,MATCH($A47,[1]ТУ!$A:$A,0),3+J$7),"*","")) -> #N/A | K47: =TRIM(SUBSTITUTE(INDEX([1]ТУ!$A:$G,MATCH($A47,[1]ТУ!$A:$A,0),3+K$7),"*","")) -> #N/A | L47: =TRIM(SUBSTITUTE(INDEX([1]ТУ!$A:$G,MATCH($A47,[1]ТУ!$A:$A,0),3+L$7),"*","")) -> #N/A | M47: =IF($A47<>"",IFERROR(IF(SUBSTITUTE(D47,",",".")<>SUBSTITUTE(SUBSTITUTE(I47,",","."),"∞","oo"),1,""),"!"),"") | N47: =IF($A47<>"",IFERROR(IF(SUBSTITUTE(E47,",",".")<>SUBSTITUTE(SUBSTITUTE(J47,",","."),"∞","oo"),1,""),"!"),"") | O47: =IF($A47<>"",IFERROR(IF(SUBSTITUTE(F47,",",".")<>SUBSTITUTE(SUBSTITUTE(K47,",","."),"∞","oo"),1,""),"!"),"") | P47: =IF($A47<>"",IFERROR(IF(SUBSTITUTE(G47,",",".")<>SUBSTITUTE(SUBSTITUTE(L47,",","."),"∞","oo"),1,""),"!"),"")
...
